Traceback (most recent call last):
  File "/home/ndsg/.local/lib/python3.6/site-packages/websockets/protocol.py", line 674, in transfer_data
    message = yield from self.read_message()
  File "/home/ndsg/.local/lib/python3.6/site-packages/websockets/protocol.py", line 742, in read_message
    frame = yield from self.read_data_frame(max_size=self.max_size)
  File "/home/ndsg/.local/lib/python3.6/site-packages/websockets/protocol.py", line 835, in read_data_frame
    yield from self.pong(frame.data)
  File "/home/ndsg/.local/lib/python3.6/site-packages/websockets/protocol.py", line 618, in pong
    yield from self.write_frame(True, OP_PONG, data)
  File "/home/ndsg/.local/lib/python3.6/site-packages/websockets/protocol.py", line 919, in write_frame
    yield from self.ensure_open()
  File "/home/ndsg/.local/lib/python3.6/site-packages/websockets/protocol.py", line 646, in ensure_open
    ) from self.transfer_data_exc
websockets.exceptions.ConnectionClosed: WebSocket connection is closed: code = 1006 (connection closed abnormally [internal]), no reason

The above exception was the direct cause of the following exception:

Traceback (most recent call last):
  File "main_server.py", line 60, in queue_handler
    await websocket.send(CURRENTLY_SERVING[client_hash])
  File "/home/ndsg/.local/lib/python3.6/site-packages/websockets/protocol.py", line 467, in send
    yield from self.write_frame(True, OP_TEXT, data.encode('utf-8'))
  File "/home/ndsg/.local/lib/python3.6/site-packages/websockets/protocol.py", line 919, in write_frame
    yield from self.ensure_open()
  File "/home/ndsg/.local/lib/python3.6/site-packages/websockets/protocol.py", line 646, in ensure_open
    ) from self.transfer_data_exc
websockets.exceptions.ConnectionClosed: WebSocket connection is closed: code = 1006 (connection closed abnormally [internal]), no reason
Traceback (most recent call last):
  File "main_server.py", line 57, in queue_handler
    await websocket.send(get_queue_placement(client_hash))
  File "/home/ndsg/.local/lib/python3.6/site-packages/websockets/protocol.py", line 467, in send
    yield from self.write_frame(True, OP_TEXT, data.encode('utf-8'))
  File "/home/ndsg/.local/lib/python3.6/site-packages/websockets/protocol.py", line 919, in write_frame
    yield from self.ensure_open()
  File "/home/ndsg/.local/lib/python3.6/site-packages/websockets/protocol.py", line 646, in ensure_open
    ) from self.transfer_data_exc
websockets.exceptions.ConnectionClosed: WebSocket connection is closed: code = 1006 (connection closed abnormally [internal]), no reason
Traceback (most recent call last):
  File "main_server.py", line 57, in queue_handler
    await websocket.send(get_queue_placement(client_hash))
  File "/home/ndsg/.local/lib/python3.6/site-packages/websockets/protocol.py", line 467, in send
    yield from self.write_frame(True, OP_TEXT, data.encode('utf-8'))
  File "/home/ndsg/.local/lib/python3.6/site-packages/websockets/protocol.py", line 898, in write_frame
    logger.debug("%s > %s", self.side, frame)
  File "/usr/lib/python3.6/logging/__init__.py", line 1296, in debug
    self._log(DEBUG, msg, args, **kwargs)
  File "/usr/lib/python3.6/logging/__init__.py", line 1444, in _log
    self.handle(record)
  File "/usr/lib/python3.6/logging/__init__.py", line 1454, in handle
    self.callHandlers(record)
  File "/usr/lib/python3.6/logging/__init__.py", line 1516, in callHandlers
    hdlr.handle(record)
  File "/usr/lib/python3.6/logging/__init__.py", line 865, in handle
    self.emit(record)
  File "/usr/lib/python3.6/logging/__init__.py", line 996, in emit
    stream.write(msg)
KeyboardInterrupt
Traceback (most recent call last):
  File "/home/ndsg/.local/lib/python3.6/site-packages/websockets/protocol.py", line 674, in transfer_data
    message = yield from self.read_message()
  File "/home/ndsg/.local/lib/python3.6/site-packages/websockets/protocol.py", line 742, in read_message
    frame = yield from self.read_data_frame(max_size=self.max_size)
  File "/home/ndsg/.local/lib/python3.6/site-packages/websockets/protocol.py", line 815, in read_data_frame
    frame = yield from self.read_frame(max_size)
  File "/home/ndsg/.local/lib/python3.6/site-packages/websockets/protocol.py", line 884, in read_frame
    extensions=self.extensions,
  File "/home/ndsg/.local/lib/python3.6/site-packages/websockets/framing.py", line 99, in read
    data = yield from reader(2)
  File "/usr/lib/python3.6/asyncio/streams.py", line 674, in readexactly
    yield from self._wait_for_data('readexactly')
  File "/usr/lib/python3.6/asyncio/streams.py", line 464, in _wait_for_data
    yield from self._waiter
concurrent.futures._base.CancelledError

The above exception was the direct cause of the following exception:

Traceback (most recent call last):
  File "main_server.py", line 62, in queue_handler
    await websocket.recv()
  File "/home/ndsg/.local/lib/python3.6/site-packages/websockets/protocol.py", line 434, in recv
    yield from self.ensure_open()
  File "/home/ndsg/.local/lib/python3.6/site-packages/websockets/protocol.py", line 658, in ensure_open
    ) from self.transfer_data_exc
websockets.exceptions.ConnectionClosed: WebSocket connection is closed: code = 1006 (connection closed abnormally [internal]), no reason
Traceback (most recent call last):
  File "/home/ndsg/.local/lib/python3.6/site-packages/websockets/protocol.py", line 674, in transfer_data
    message = yield from self.read_message()
  File "/home/ndsg/.local/lib/python3.6/site-packages/websockets/protocol.py", line 742, in read_message
    frame = yield from self.read_data_frame(max_size=self.max_size)
  File "/home/ndsg/.local/lib/python3.6/site-packages/websockets/protocol.py", line 815, in read_data_frame
    frame = yield from self.read_frame(max_size)
  File "/home/ndsg/.local/lib/python3.6/site-packages/websockets/protocol.py", line 884, in read_frame
    extensions=self.extensions,
  File "/home/ndsg/.local/lib/python3.6/site-packages/websockets/framing.py", line 99, in read
    data = yield from reader(2)
  File "/usr/lib/python3.6/asyncio/streams.py", line 674, in readexactly
    yield from self._wait_for_data('readexactly')
  File "/usr/lib/python3.6/asyncio/streams.py", line 464, in _wait_for_data
    yield from self._waiter
concurrent.futures._base.CancelledError

The above exception was the direct cause of the following exception:

Traceback (most recent call last):
  File "main_server.py", line 62, in queue_handler
    await websocket.recv()
  File "/home/ndsg/.local/lib/python3.6/site-packages/websockets/protocol.py", line 434, in recv
    yield from self.ensure_open()
  File "/home/ndsg/.local/lib/python3.6/site-packages/websockets/protocol.py", line 658, in ensure_open
    ) from self.transfer_data_exc
websockets.exceptions.ConnectionClosed: WebSocket connection is closed: code = 1006 (connection closed abnormally [internal]), no reason
Traceback (most recent call last):
  File "main_server.py", line 62, in queue_handler
    await websocket.recv()
  File "/home/ndsg/.local/lib/python3.6/site-packages/websockets/protocol.py", line 434, in recv
    yield from self.ensure_open()
  File "/home/ndsg/.local/lib/python3.6/site-packages/websockets/protocol.py", line 658, in ensure_open
    ) from self.transfer_data_exc
websockets.exceptions.ConnectionClosed: WebSocket connection is closed: code = 1011 (unexpected error), no reason
Traceback (most recent call last):
  File "main_server.py", line 62, in queue_handler
    await websocket.recv()
  File "/home/ndsg/.local/lib/python3.6/site-packages/websockets/protocol.py", line 434, in recv
    yield from self.ensure_open()
  File "/home/ndsg/.local/lib/python3.6/site-packages/websockets/protocol.py", line 658, in ensure_open
    ) from self.transfer_data_exc
websockets.exceptions.ConnectionClosed: WebSocket connection is closed: code = 1011 (unexpected error), no reason
Traceback (most recent call last):
  File "main_server.py", line 62, in queue_handler
    await websocket.recv()
  File "/home/ndsg/.local/lib/python3.6/site-packages/websockets/protocol.py", line 434, in recv
    yield from self.ensure_open()
  File "/home/ndsg/.local/lib/python3.6/site-packages/websockets/protocol.py", line 658, in ensure_open
    ) from self.transfer_data_exc
websockets.exceptions.ConnectionClosed: WebSocket connection is closed: code = 1011 (unexpected error), no reason
Traceback (most recent call last):
  File "main_server.py", line 62, in queue_handler
    await websocket.recv()
  File "/home/ndsg/.local/lib/python3.6/site-packages/websockets/protocol.py", line 434, in recv
    yield from self.ensure_open()
  File "/home/ndsg/.local/lib/python3.6/site-packages/websockets/protocol.py", line 658, in ensure_open
    ) from self.transfer_data_exc
websockets.exceptions.ConnectionClosed: WebSocket connection is closed: code = 1011 (unexpected error), no reason
Traceback (most recent call last):
  File "main_server.py", line 57, in queue_handler
    await websocket.send(get_queue_placement(client_hash))
  File "/home/ndsg/.local/lib/python3.6/site-packages/websockets/protocol.py", line 467, in send
    yield from self.write_frame(True, OP_TEXT, data.encode('utf-8'))
  File "/home/ndsg/.local/lib/python3.6/site-packages/websockets/protocol.py", line 913, in write_frame
    yield from self.writer.drain()
  File "/usr/lib/python3.6/asyncio/streams.py", line 339, in drain
    yield from self._protocol._drain_helper()
  File "/usr/lib/python3.6/asyncio/streams.py", line 217, in _drain_helper
    yield from waiter
  File "/usr/lib/python3.6/asyncio/selector_events.py", line 775, in _write_ready
    n = self._sock.send(self._buffer)
TimeoutError: [Errno 110] Connection timed out
Traceback (most recent call last):
  File "main_server.py", line 62, in queue_handler
    await websocket.recv()
  File "/home/ndsg/.local/lib/python3.6/site-packages/websockets/protocol.py", line 434, in recv
    yield from self.ensure_open()
  File "/home/ndsg/.local/lib/python3.6/site-packages/websockets/protocol.py", line 658, in ensure_open
    ) from self.transfer_data_exc
websockets.exceptions.ConnectionClosed: WebSocket connection is closed: code = 1011 (unexpected error), no reason
Traceback (most recent call last):
  File "main_server.py", line 62, in queue_handler
    await websocket.recv()
  File "/home/ndsg/.local/lib/python3.6/site-packages/websockets/protocol.py", line 434, in recv
    yield from self.ensure_open()
  File "/home/ndsg/.local/lib/python3.6/site-packages/websockets/protocol.py", line 658, in ensure_open
    ) from self.transfer_data_exc
websockets.exceptions.ConnectionClosed: WebSocket connection is closed: code = 1011 (unexpected error), no reason
